<?xml version="1.0" encoding="utf-8"?>
<!-- =================================================================================== -->
<!-- |    This document was autogenerated by xacro from ../xacro/my_robot_integration.urdf.xacro | -->
<!-- |    EDITING THIS FILE BY HAND IS NOT RECOMMENDED                                 | -->
<!-- =================================================================================== -->
<!-- Name your robot here -->
<robot name="FirstTry_URDF">
  <link name="dummy_link">
  </link>
  <joint name="dummy_joint" type="fixed">
    <parent link="dummy_link"/>
    <child link="chasis"/>
    <origin rpy="0 0 0" xyz="0 0 0"/>
    <axis xyz="0 0 0"/>
  </joint>
  <link name="chasis">
    <inertial>
      <origin rpy="0 0 0" xyz="0.0 0.0 -5.0"/>
      <mass value="10.00"/>
      <inertia ixx="1.12027870972558" ixy="-0.0185928970398008" ixz="0.00190686378820933" iyy="4.9468392282957" iyz="0.000937459767783745" izz="3.93286745360775"/>
    </inertial>
    <visual>
      <origin rpy="0 0 0" xyz="0 0 0"/>
      <geometry>
        <mesh filename="package://FirstTry_URDF/meshes/chasis.STL"/>
      </geometry>
      <material name="">
        <color rgba="0.792156862745098 0.819607843137255 0.933333333333333 1"/>
      </material>
    </visual>
    <collision>
      <origin rpy="0 0 0" xyz="0 0 0"/>
      <geometry>
        <mesh filename="package://FirstTry_URDF/meshes/chasis.STL"/>
      </geometry>
    </collision>
  </link>
  <link name="rear_axle">
    <inertial>
      <origin rpy="0 0 0" xyz="0 0.196163628606691 0"/>
      <mass value="0.5"/>
      <inertia ixx="0.0286856446413934" ixy="3.11616198099933E-35" ixz="1.93945645430612E-36" iyy="0.0256908677693375" iyz="-9.46644021851406E-20" izz="0.0286856446413934"/>
    </inertial>
    <visual>
      <origin rpy="0 0 0" xyz="0 0 0"/>
      <geometry>
        <mesh filename="package://FirstTry_URDF/meshes/rear_axle.STL"/>
      </geometry>
      <material name="">
        <color rgba="0.792156862745098 0.819607843137255 0.933333333333333 1"/>
      </material>
    </visual>
    <collision>
      <origin rpy="0 0 0" xyz="0 0 0"/>
      <geometry>
        <mesh filename="package://FirstTry_URDF/meshes/rear_axle.STL"/>
      </geometry>
    </collision>
  </link>
  <joint name="rear_axle_joint" type="revolute">
    <origin rpy="3.1416 0 0" xyz="-0.17411 0 -0.1397"/>
    <parent link="chasis"/>
    <child link="rear_axle"/>
    <axis xyz="0 1 0"/>
    <limit effort="10" lower="-1000000" upper="1000000" velocity="100"/>
  </joint>
  <link name="right_castor">
    <inertial>
      <origin rpy="0 0 0" xyz="-5.55111512312578E-17 -0.0574241163490277 -1.11022302462516E-16"/>
      <mass value="0.5"/>
      <inertia ixx="0.00457350619640945" ixy="2.46250393206182E-19" ixz="-5.96161204032111E-19" iyy="0.00432500957891741" iyz="3.05894930708921E-19" izz="0.00570892208149707"/>
    </inertial>
    <visual>
      <origin rpy="0 0 0" xyz="0 0 0"/>
      <geometry>
        <mesh filename="package://FirstTry_URDF/meshes/right_castor.STL"/>
      </geometry>
      <material name="">
        <color rgba="0.792156862745098 0.819607843137255 0.933333333333333 1"/>
      </material>
    </visual>
    <collision>
      <origin rpy="0 0 0" xyz="0 0 0"/>
      <geometry>
        <mesh filename="package://FirstTry_URDF/meshes/right_castor.STL"/>
      </geometry>
    </collision>
  </link>
  <joint name="right_castor_joint" type="revolute">
    <origin rpy="1.5708 0 0" xyz="0.33389 -0.34856 0"/>
    <parent link="chasis"/>
    <child link="right_castor"/>
    <axis xyz="0 1 0"/>
    <limit effort="10" lower="-1000000" upper="1000000" velocity="100"/>
  </joint>
  <link name="right_wheel">
    <inertial>
      <origin rpy="0 0 0" xyz="0 1.27000000000321E-05 0"/>
      <mass value="0.5"/>
      <inertia ixx="0.00747310310032442" ixy="-2.0218146735629E-35" ixz="-9.69728227153091E-37" iyy="0.0127042752705515" iyz="1.54905385393867E-19" izz="0.00747310310032442"/>
    </inertial>
    <visual>
      <origin rpy="0 0 0" xyz="0 0 0"/>
      <geometry>
        <mesh filename="package://FirstTry_URDF/meshes/right_wheel.STL"/>
      </geometry>
      <material name="">
        <color rgba="0.792156862745098 0.819607843137255 0.933333333333333 1"/>
      </material>
    </visual>
    <collision>
      <origin rpy="0 0 0" xyz="0 0 0"/>
      <geometry>
        <mesh filename="package://FirstTry_URDF/meshes/right_wheel.STL"/>
      </geometry>
    </collision>
  </link>
  <joint name="right_wheel_joint" type="revolute">
    <origin rpy="-1.5708 0 0" xyz="0 -0.1397 0"/>
    <parent link="right_castor"/>
    <child link="right_wheel"/>
    <axis xyz="0 1 0"/>
    <limit effort="10" lower="-1000000" upper="1000000" velocity="100"/>
  </joint>
  <link name="left_castor">
    <inertial>
      <origin rpy="0 0 0" xyz="0 -0.0574241163490277 3.38271077815477E-17"/>
      <mass value="0.5"/>
      <inertia ixx="0.00747310310032442" ixy="-2.0218146735629E-35" ixz="-9.69728227153071E-37" iyy="0.0127042752705515" iyz="2.58175642323111E-20" izz="0.00747310310032442"/>
    </inertial>
    <visual>
      <origin rpy="0 0 0" xyz="0 0 0"/>
      <geometry>
        <mesh filename="package://FirstTry_URDF/meshes/left_castor.STL"/>
      </geometry>
      <material name="">
        <color rgba="0.792156862745098 0.819607843137255 0.933333333333333 1"/>
      </material>
    </visual>
    <collision>
      <origin rpy="0 0 0" xyz="0 0 0"/>
      <geometry>
        <mesh filename="package://FirstTry_URDF/meshes/left_castor.STL"/>
      </geometry>
    </collision>
  </link>
  <joint name="left_castor_joint" type="revolute">
    <origin rpy="1.5708 0 0" xyz="0.33389 0.0070364 0"/>
    <parent link="chasis"/>
    <child link="left_castor"/>
    <axis xyz="0 1 0"/>
    <limit effort="10" lower="-1000000" upper="1000000" velocity="100"/>
  </joint>
  <link name="left_wheel">
    <inertial>
      <origin rpy="0 0 0" xyz="1.11022302462516E-16 1.27000000000044E-05 0"/>
      <mass value="0.5"/>
      <inertia ixx="0.00747310310032442" ixy="-2.0218146735629E-35" ixz="-9.69728227153071E-37" iyy="0.0127042752705515" iyz="2.58175642323111E-20" izz="0.00747310310032442"/>
    </inertial>
    <visual>
      <origin rpy="0 0 0" xyz="0 0 0"/>
      <geometry>
        <mesh filename="package://FirstTry_URDF/meshes/left_wheel.STL"/>
      </geometry>
      <material name="">
        <color rgba="0.792156862745098 0.819607843137255 0.933333333333333 1"/>
      </material>
    </visual>
    <collision>
      <origin rpy="0 0 0" xyz="0 0 0"/>
      <geometry>
        <mesh filename="package://FirstTry_URDF/meshes/left_wheel.STL"/>
      </geometry>
    </collision>
  </link>
  <joint name="left_wheel_joint" type="revolute">
    <origin rpy="-1.5708 0 0" xyz="0 -0.1397 0"/>
    <parent link="left_castor"/>
    <child link="left_wheel"/>
    <axis xyz="0 1 0"/>
    <limit effort="10" lower="-1000000" upper="1000000" velocity="100"/>
  </joint>
  <transmission name="rear_motor">
    <type>transmission_interface/SimpleTransmission</type>
    <joint name="rear_axle_joint">
      <hardwareInterface>hardware_interface/VelocityJointInterface</hardwareInterface>
    </joint>
    <actuator name="rear_motor">
      <mechanicalReduction>50</mechanicalReduction>
      <hardwareInterface>hardware_interface/VelocityJointInterface</hardwareInterface>
    </actuator>
  </transmission>
  <transmission name="right_castor_motor">
    <type>transmission_interface/SimpleTransmission</type>
    <joint name="right_castor_joint">
      <hardwareInterface>hardware_interface/EffortJointInterface</hardwareInterface>
    </joint>
    <actuator name="right_castor_motor">
      <mechanicalReduction>50</mechanicalReduction>
      <hardwareInterface>hardware_interface/EffortJointInterface</hardwareInterface>
    </actuator>
  </transmission>
  <transmission name="left_castor_motor">
    <type>transmission_interface/SimpleTransmission</type>
    <joint name="left_castor_joint">
      <hardwareInterface>hardware_interface/EffortJointInterface</hardwareInterface>
    </joint>
    <actuator name="left_castor_motor">
      <mechanicalReduction>50</mechanicalReduction>
      <hardwareInterface>hardware_interface/EffortJointInterface</hardwareInterface>
    </actuator>
  </transmission>
  <link name="base_laser">
    <inertial>
      <origin rpy="0 0 0" xyz="-0.00029774 0.0066667 0.00013047"/>
      <mass value="0.15717"/>
      <inertia ixx="6.7885E-05" ixy="-1.3987E-07" ixz="-8.1554E-07" iyy="0.00013173" iyz="-9.0932E-08" izz="7.1972E-05"/>
    </inertial>
    <visual>
      <origin rpy="0 0 0" xyz="0 0 0"/>
      <geometry>
        <mesh filename="package://ydlidar_ros/meshes/ydlidar.dae"/>
      </geometry>
      <material name="">
        <color rgba="0.64706 0.61961 0.58824 1"/>
      </material>
    </visual>
    <collision>
      <origin rpy="0 0 0" xyz="0 0 0"/>
      <geometry>
        <mesh filename="package://ydlidar_ros/meshes/ydlidar.dae"/>
      </geometry>
    </collision>
  </link>
  <link name="laser_frame">
    <inertial>
      <origin rpy="0 0 0" xyz="-0.00036659 0.00064155 -0.00027052"/>
      <mass value="0.25482"/>
      <inertia ixx="8.9194E-05" ixy="1.8116E-07" ixz="3.6435E-08" iyy="0.00018279" iyz="2.423E-07" izz="0.00011103"/>
    </inertial>
    <!--visual>
      <origin
        xyz="0 0 0"
        rpy="0 0 0" />
      <geometry>
        <mesh
          filename="package://ydlidar_ros/meshes/ydlidar.dae" />
      </geometry>
      <material
        name="">
        <color
          rgba="0.64706 0.61961 0.58824 1" />
      </material>
    </visual-->
    <!--collision>
      <origin
        xyz="0 0 0"
        rpy="0 0 0" />
      <geometry>
        <mesh
          filename="package://ydlidar_ros/meshes/ydlidar.dae" />
      </geometry>
    </collision-->
  </link>
  <joint name="laser_joint" type="fixed">
    <origin rpy="0 0 0" xyz="0 0 0.03172"/>
    <parent link="base_laser"/>
    <child link="laser_frame"/>
    <axis xyz="0 0 0"/>
  </joint>

  <joint name="lidar_joint" type="fixed">
    <origin rpy="0 0 0" xyz="0 0 0.03172"/>
    <parent link="chasis"/>
    <child link="base_laser"/>
    <axis xyz="0 0 0"/>
  </joint>
  <!-- <xacro:include filename=""/> -->
  <!-- Add your gazebo sensors here -->
  <!--  Gazebo plugin for control here is already added for you -->
  <gazebo>
    <plugin filename="libgazebo_ros_control.so" name="gazebo_ros_control">
      <robotNamespace>/FirstTry_URDF</robotNamespace>
      <robotSimType>gazebo_ros_control/DefaultRobotHWSim</robotSimType>
      <legacyModeNS>true</legacyModeNS>
    </plugin>
  </gazebo>
  <!-- Create a joint between your robot and sensor -->
</robot>
